<?xml version="1.0" ?>
<robot name="AMR" xmlns:xacro="http://www.ros.org/wiki/xacro">

<xacro:include filename="$(find AMR_description)/urdf/materials.xacro" />
<xacro:include filename="$(find AMR_description)/urdf/AMR.trans" />
<xacro:include filename="$(find AMR_description)/urdf/AMR.gazebo" />

<link name="base_link">
  <inertial>
    <origin xyz="-0.004839713101956054 -0.005950095714770901 0.035506125326520636" rpy="0 0 0"/>
    <mass value="2.995074243807502"/>
    <inertia ixx="0.007941" iyy="0.010341" izz="0.016125" ixy="1e-06" iyz="0.0" ixz="-0.0"/>
  </inertial>
  <visual>
    <origin xyz="0 0 0" rpy="0 0 0"/>
    <geometry>
      <mesh filename="file://$(find AMR_description)/meshes/base_link.stl" scale="0.001 0.001 0.001"/>
    </geometry>
    <material name="silver"/>
  </visual>
  <collision>
    <origin xyz="0 0 0" rpy="0 0 0"/>
    <geometry>
      <mesh filename="file://$(find AMR_description)/meshes/base_link.stl" scale="0.001 0.001 0.001"/>
    </geometry>
  </collision>
</link>

<link name="wheel1_1">
  <inertial>
    <origin xyz="0.0048523143384312725 0.0075321405896599525 -0.00718351564932343" rpy="0 0 0"/>
    <mass value="0.30408136956739273"/>
    <inertia ixx="9.7e-05" iyy="0.000161" izz="9.7e-05" ixy="0.0" iyz="-0.0" ixz="-0.0"/>
  </inertial>
  <visual>
    <origin xyz="-0.046315 0.10765 -0.037844" rpy="0 0 0"/>
    <geometry>
      <mesh filename="file://$(find AMR_description)/meshes/wheel1_1.stl" scale="0.001 0.001 0.001"/>
    </geometry>
    <material name="silver"/>
  </visual>
  <collision>
    <origin xyz="-0.046315 0.10765 -0.037844" rpy="0 0 0"/>
    <geometry>
      <mesh filename="file://$(find AMR_description)/meshes/wheel1_1.stl" scale="0.001 0.001 0.001"/>
    </geometry>
  </collision>
</link>

<link name="wheel4_1">
  <inertial>
    <origin xyz="0.004852314338431266 0.00436766798079824 -0.007160466136070822" rpy="0 0 0"/>
    <mass value="0.30408136956739273"/>
    <inertia ixx="9.7e-05" iyy="0.000161" izz="9.7e-05" ixy="-0.0" iyz="-0.0" ixz="0.0"/>
  </inertial>
  <visual>
    <origin xyz="0.065685 -0.08385 -0.037844" rpy="0 0 0"/>
    <geometry>
      <mesh filename="file://$(find AMR_description)/meshes/wheel4_1.stl" scale="0.001 0.001 0.001"/>
    </geometry>
    <material name="silver"/>
  </visual>
  <collision>
    <origin xyz="0.065685 -0.08385 -0.037844" rpy="0 0 0"/>
    <geometry>
      <mesh filename="file://$(find AMR_description)/meshes/wheel4_1.stl" scale="0.001 0.001 0.001"/>
    </geometry>
  </collision>
</link>

<link name="wheel2_1">
  <inertial>
    <origin xyz="0.0048523723536919305 0.004367529444894644 -0.0071835630076764745" rpy="0 0 0"/>
    <mass value="0.304087148511518"/>
    <inertia ixx="9.7e-05" iyy="0.000161" izz="9.7e-05" ixy="-0.0" iyz="-0.0" ixz="-0.0"/>
  </inertial>
  <visual>
    <origin xyz="-0.046315 -0.08385 -0.037844" rpy="0 0 0"/>
    <geometry>
      <mesh filename="file://$(find AMR_description)/meshes/wheel2_1.stl" scale="0.001 0.001 0.001"/>
    </geometry>
    <material name="silver"/>
  </visual>
  <collision>
    <origin xyz="-0.046315 -0.08385 -0.037844" rpy="0 0 0"/>
    <geometry>
      <mesh filename="file://$(find AMR_description)/meshes/wheel2_1.stl" scale="0.001 0.001 0.001"/>
    </geometry>
  </collision>
</link>

<link name="wheel3_1">
  <inertial>
    <origin xyz="0.004852372353691507 0.007532279125563535 -0.007160418777717916" rpy="0 0 0"/>
    <mass value="0.304087148511518"/>
    <inertia ixx="9.7e-05" iyy="0.000161" izz="9.7e-05" ixy="0.0" iyz="-0.0" ixz="0.0"/>
  </inertial>
  <visual>
    <origin xyz="0.065685 0.10765 -0.037844" rpy="0 0 0"/>
    <geometry>
      <mesh filename="file://$(find AMR_description)/meshes/wheel3_1.stl" scale="0.001 0.001 0.001"/>
    </geometry>
    <material name="silver"/>
  </visual>
  <collision>
    <origin xyz="0.065685 0.10765 -0.037844" rpy="0 0 0"/>
    <geometry>
      <mesh filename="file://$(find AMR_description)/meshes/wheel3_1.stl" scale="0.001 0.001 0.001"/>
    </geometry>
  </collision>
</link>

<link name="lidar_1">
  <inertial>
    <origin xyz="8.544929735477408e-05 -9.563423499811454e-05 0.013716599681915076" rpy="0 0 0"/>
    <mass value="0.25084239440031786"/>
    <inertia ixx="0.00011" iyy="0.000109" izz="0.000154" ixy="-0.0" iyz="-0.0" ixz="0.0"/>
  </inertial>
  <visual>
    <origin xyz="-0.035157 0.00595 -0.087785" rpy="0 0 0"/>
    <geometry>
      <mesh filename="file://$(find AMR_description)/meshes/lidar_1.stl" scale="0.001 0.001 0.001"/>
    </geometry>
    <material name="silver"/>
  </visual>
  <collision>
    <origin xyz="-0.035157 0.00595 -0.087785" rpy="0 0 0"/>
    <geometry>
      <mesh filename="file://$(find AMR_description)/meshes/lidar_1.stl" scale="0.001 0.001 0.001"/>
    </geometry>
  </collision>
</link>

<joint name="wheel1_joint" type="continuous">
  <origin xyz="0.046315 -0.10765 0.037844" rpy="0 0 0"/>
  <parent link="base_link"/>
  <child link="wheel1_1"/>
  <axis xyz="-0.0 1.0 0.0"/>
</joint>

<joint name="wheel4_joint" type="continuous">
  <origin xyz="-0.065685 0.08385 0.037844" rpy="0 0 0"/>
  <parent link="base_link"/>
  <child link="wheel4_1"/>
  <axis xyz="-0.0 -1.0 -0.0"/>
</joint>

<joint name="wheel2_joint" type="continuous">
  <origin xyz="0.046315 0.08385 0.037844" rpy="0 0 0"/>
  <parent link="base_link"/>
  <child link="wheel2_1"/>
  <axis xyz="-0.0 -1.0 -0.0"/>
</joint>

<joint name="wheel3_joint" type="continuous">
  <origin xyz="-0.065685 -0.10765 0.037844" rpy="0 0 0"/>
  <parent link="base_link"/>
  <child link="wheel3_1"/>
  <axis xyz="-0.0 1.0 0.0"/>
</joint>

<joint name="lidar1_joint" type="fixed">
  <origin xyz="0.035157 -0.00595 0.087785" rpy="0 0 0"/>
  <parent link="base_link"/>
  <child link="lidar_1"/>
</joint>
</robot>
